Workbook

Sheet START HERE
B1: How to work the list
A3: 1 | B3: Open your tab | C3: RAM or SHYAM. Start at row 1.
A4: 2 | B4: Do what column G says | C4: Click Call. Then book, or send the WhatsApp, as column G says.
A5: 3 | B5: Log it | C5: Go to LOG. Add ONE line: time (Ctrl+Shift+;), your name, the phone, the outcome. Request ID only if the answer is about one of their requests.
A6: 4 | B6: Repeat | C6: Go back to your tab. The row you finished goes away and the next one moves up.
B8: Which outcome?
B9: Outcome | C9: When
B10: NO_ANSWER | C10: Called, no answer. You sent the WhatsApp.
B11: CALL_BACK | C11: They picked up but asked you to call later.
B12: BOOKED | C12: You booked the interview for them in the partner's calendar.
B13: SENT_LINK | C13: They said yes; you sent the partner's booking link. NOT a booking: it counts only once they book.
B14: NOT_INTERESTED | C14: They no longer want this interview.
B15: STOP | C15: They asked us to stop contacting them.
B16: WRONG_NUMBER | C16: Wrong number, or not their WhatsApp.
B17: SELF_BOOKED | C17: Their booking is already in the partner's calendar (they did it).
B18: NO_SLOTS | C18: The partner's calendar has no free time. Write that request's ID in E.
B20: Good to know
B21: Two requests, two answers | C21: Yes to one, no to the other? Write two lines: BOOKED and NOT_INTERESTED, each with its request ID (R0..) in column E. Copy the ID from column D of your list. Blank E means all their open requests.
B22: Link sent is not booked | C22: SENT_LINK only means they have the link. The row comes back later so you can check it was booked.
B23: Someone replies later | C23: Type their phone in the yellow box at the top of your tab ("Reply or call-back? Phone"). It shows what to book.
B24: Orange cell in LOG | C24: Something is wrong with that line. Column J says what. Fix it.
B25: Yellow row | C25: Less than 4 hours left. These rows are already at the top.
B26: Never | C26: Contact anyone before 10:00 or after 21:00. Promise anything about the job or the salary. Change other tabs.
B27: Not sure? | C27: Write it in Notes and ask your lead.

Sheet RAM
A1: RAM: your list. Start at the top. Do what column G says.
B2: Ram | C2: Time now | D2: =SETTINGS!$B$4 -> 46309.828 | G2: =C3&" people waiting" -> 0 people waiting | N2: =SETTINGS!$B$14 -> 4
A3: =IF(ROUND(MOD(SETTINGS!$B$4,1)*1440,0)<ROUND(SETTINGS!$B$9*1440,0),"Your shift has not started. Nothing to do yet.",IF(ROUND(MOD(SETTINGS!$B$4,1)*1440,0)>=ROUND(SETTINGS!$B$10*1440,0),"Your shift is over. Thank you!",IF($C$3=0,"Nothing waiting right now. Check LOG column J for lines marked in orange.",""))) -> Your shift is over. Thank you! | C3: =SUMPRODUCT((DESK!$Z$2:$Z$601=$B$2)*(DESK!$AI$2:$AI$601<>"")) -> 0
A4: Reply or call-back? Phone: | E4: =IF($D$4="","",IF(IFERROR(MATCH($D$4&"|1",DESK!$AJ$2:$AJ$601,0),"")="","Not on the open list (already done, or wrong number).",INDEX(DESK!$AW$2:$AW$601,IFERROR(MATCH($D$4&"|1",DESK!$AJ$2:$AJ$601,0),""))&" "&INDEX(DESK!$B$2:$B$601,IFERROR(MATCH($D$4&"|1",DESK!$AJ$2:$AJ$601,0),""))&" "&INDEX(DESK!$G$2:$G$601,IFERROR(MATCH($D$4&"|1",DESK!$AJ$2:$AJ$601,0),""))&IF(IFERROR(MATCH($D$4&"|2",DESK!$AJ$2:$AJ$601,0),"")="","","; "&INDEX(DESK!$AW$2:$AW$601,IFERROR(MATCH($D$4&"|2",DESK!$AJ$2:$AJ$601,0),""))&" "&INDEX(DESK!$B$2:$B$601,IFERROR(MATCH($D$4&"|2",DESK!$AJ$2:$AJ$601,0),""))&" "&INDEX(DESK!$G$2:$G$601,IFERROR(MATCH($D$4&"|2",DESK!$AJ$2:$AJ$601,0),"")))&IF(IFERROR(MATCH($D$4&"|3",DESK!$AJ$2:$AJ$601,0),"")="","","; "&INDEX(DESK!$AW$2:$AW$601,IFERROR(MATCH($D$4&"|3",DESK!$AJ$2:$AJ$601,0),""))&" "&INDEX(DESK!$B$2:$B$601,IFERROR(MATCH($D$4&"|3",DESK!$AJ$2:$AJ$601,0),""))&" "&INDEX(DESK!$G$2:$G$601,IFERROR(MATCH($D$4&"|3",DESK!$AJ$2:$AJ$601,0),"")))&IF(INDEX(DESK!$AC$2:$AC$601,IFERROR(MATCH($D$4&"|1",DESK!$AJ$2:$AJ$601,0),""))="YES"," : they said yes? Book it, log BOOKED."," : send the link, log SENT_LINK."))) | J4: =IF(IFERROR(MATCH($D$4&"|1",DESK!$AJ$2:$AJ$601,0),"")="","",HYPERLINK(INDEX(DESK!$AD$2:$AD$601,IFERROR(MATCH($D$4&"|1",DESK!$AJ$2:$AJ$601,0),"")),"Calendar: "&INDEX(DESK!$B$2:$B$601,IFERROR(MATCH($D$4&"|1",DESK!$AJ$2:$AJ$601,0),"")))) | K4: =IF(IFERROR(MATCH($D$4&"|2",DESK!$AJ$2:$AJ$601,0),"")="","",HYPERLINK(INDEX(DESK!$AD$2:$AD$601,IFERROR(MATCH($D$4&"|2",DESK!$AJ$2:$AJ$601,0),"")),"Calendar: "&INDEX(DESK!$B$2:$B$601,IFERROR(MATCH($D$4&"|2",DESK!$AJ$2:$AJ$601,0),"")))) | L4: =IF(IFERROR(MATCH($D$4&"|3",DESK!$AJ$2:$AJ$601,0),"")="","",HYPERLINK(INDEX(DESK!$AD$2:$AD$601,IFERROR(MATCH($D$4&"|3",DESK!$AJ$2:$AJ$601,0),"")),"Calendar: "&INDEX(DESK!$B$2:$B$601,IFERROR(MATCH($D$4&"|3",DESK!$AJ$2:$AJ$601,0),""))))
A6: # | B6: Candidate | C6: Phone | D6: Interviews to book (request ID first) | E6: Hours left | F6: Try | G6: WHAT TO DO | H6: Call | I6: WhatsApp | J6: Calendar 1 | K6: Calendar 2 | L6: Calendar 3 | M6: Message (copy if WhatsApp opens empty) | N6: key | O6: row | P6: msg
A7: 1 | B7: =IF(O7="","",INDEX(DESK!$D$2:$D$601,O7)) | C7: =IF(O7="","",INDEX(DESK!$F$2:$F$601,O7)) | D7: =IF(O7="","",INDEX(DESK!$AW$2:$AW$601,O7)&" "&INDEX(DESK!$B$2:$B$601,O7)&" "&INDEX(DESK!$G$2:$G$601,O7)&IFERROR("; "&INDEX(DESK!$AW$2:$AW$601,MATCH($C7&"|2",DESK!$AJ$2:$AJ$601,0))&" "&INDEX(DESK!$B$2:$B$601,MATCH($C7&"|2",DESK!$AJ$2:$AJ$601,0))&" "&INDEX(DESK!$G$2:$G$601,MATCH($C7&"|2",DESK!$AJ$2:$AJ$601,0)),"")&IFERROR("; "&INDEX(DESK!$AW$2:$AW$601,MATCH($C7&"|3",DESK!$AJ$2:$AJ$601,0))&" "&INDEX(DESK!$B$2:$B$601,MATCH($C7&"|3",DESK!$AJ$2:$AJ$601,0))&" "&INDEX(DESK!$G$2:$G$601,MATCH($C7&"|3",DESK!$AJ$2:$AJ$601,0)),"")) | E7: =IF(O7="","",ROUND(INDEX(DESK!$W$2:$W$601,O7),1)) | F7: =IF(O7="","",INDEX(DESK!$Q$2:$Q$601,O7)+1) | G7: =IF(O7="","",IF((INDEX(DESK!$AU$2:$AU$601,O7)=1),IF((INDEX(DESK!$AC$2:$AC$601,O7)="YES"),"REPLIED YES on WhatsApp. Open Calendar 1, book the first free slot, WhatsApp them the time, log BOOKED.","REPLIED YES on WhatsApp. Send the WhatsApp (it has the booking link), log SENT_LINK."),IF(F7>=SETTINGS!$B$6,"LAST TRY. ","")&IF((INDEX(DESK!$S$2:$S$601,O7)="SENT_LINK"),"Open Calendar 1. Already booked? Log SELF_BOOKED. Not booked? Call, send the WhatsApp, log what happened.",IF((INDEX(DESK!$AC$2:$AC$601,O7)="YES"),"Call. They say yes? Open Calendar 1, book the first time that suits them, log BOOKED. No answer? Send the WhatsApp, log NO_ANSWER.","Call. They say yes? Send the WhatsApp (it has the booking link), log SENT_LINK. No answer? Send the WhatsApp, log NO_ANSWER.")))&IF(INDEX(DESK!$AS$2:$AS$601,O7)="FAILED"," (Our WhatsApp did not deliver: call only.)","")) | H7: =IF(O7="","",HYPERLINK("tel:+91"&C7,"Call "&C7)) | I7: =IF(O7="","",IF(LEN("https://wa.me/91"&C7&"?text="&_xlfn.ENCODEURL(M7))<=255,HYPERLINK("https://wa.me/91"&C7&"?text="&_xlfn.ENCODEURL(M7),"Open WhatsApp"),HYPERLINK("https://wa.me/91"&C7,"Open WhatsApp, paste column M"))) | J7: =IF(O7="","",HYPERLINK(INDEX(DESK!$AD$2:$AD$601,O7),INDEX(DESK!$B$2:$B$601,O7))) | K7: =IF(O7="","",IFERROR(HYPERLINK(INDEX(DESK!$AD$2:$AD$601,MATCH($C7&"|2",DESK!$AJ$2:$AJ$601,0)),INDEX(DESK!$B$2:$B$601,MATCH($C7&"|2",DESK!$AJ$2:$AJ$601,0))),"")) | L7: =IF(O7="","",IFERROR(HYPERLINK(INDEX(DESK!$AD$2:$AD$601,MATCH($C7&"|3",DESK!$AJ$2:$AJ$601,0)),INDEX(DESK!$B$2:$B$601,MATCH($C7&"|3",DESK!$AJ$2:$AJ$601,0))),"")) | M7: =IF(O7="","",SUBSTITUTE(SUBSTITUTE(SUBSTITUTE(SUBSTITUTE(INDEX(LISTS!$B$14:$B$19,MATCH(P7,LISTS!$A$14:$A$19,0))&IF(IF((INDEX(DESK!$AC$2:$AC$601,O7)="YES"),"",INDEX(DESK!$AD$2:$AD$601,O7))="",INDEX(LISTS!$B$14:$B$19,MATCH("YES",LISTS!$A$14:$A$19,0)),INDEX(LISTS!$B$14:$B$19,MATCH("NO",LISTS!$A$14:$A$19,0))),"{NAME}",INDEX(DESK!$AQ$2:$AQ$601,O7)),"{INTERN}",$B$2),"{COMPANY}",INDEX(DESK!$B$2:$B$601,O7)&IF(INDEX(DESK!$AA$2:$AA$601,O7)>1," and "&(INDEX(DESK!$AA$2:$AA$601,O7)-1)&" more","")),"{LINK}",IF((INDEX(DESK!$AC$2:$AC$601,O7)="YES"),"",INDEX(DESK!$AD$2:$AD$601,O7)))) | N7: =$B$2&"|"&A7 -> Ram|1 | O7: =IFERROR(MATCH(N7,DESK!$AI$2:$AI$601,0),"") | P7: =IF(O7="","",IF((INDEX(DESK!$S$2:$S$601,O7)="SENT_LINK"),"CHK",IF(F7=1,"T1",IF(F7>=SETTINGS!$B$6,"T3","T2"))))
A8: 2 | B8: =IF(O8="","",INDEX(DESK!$D$2:$D$601,O8)) | C8: =IF(O8="","",INDEX(DESK!$F$2:$F$601,O8)) | D8: =IF(O8="","",INDEX(DESK!$AW$2:$AW$601,O8)&" "&INDEX(DESK!$B$2:$B$601,O8)&" "&INDEX(DESK!$G$2:$G$601,O8)&IFERROR("; "&INDEX(DESK!$AW$2:$AW$601,MATCH($C8&"|2",DESK!$AJ$2:$AJ$601,0))&" "&INDEX(DESK!$B$2:$B$601,MATCH($C8&"|2",DESK!$AJ$2:$AJ$601,0))&" "&INDEX(DESK!$G$2:$G$601,MATCH($C8&"|2",DESK!$AJ$2:$AJ$601,0)),"")&IFERROR("; "&INDEX(DESK!$AW$2:$AW$601,MATCH($C8&"|3",DESK!$AJ$2:$AJ$601,0))&" "&INDEX(DESK!$B$2:$B$601,MATCH($C8&"|3",DESK!$AJ$2:$AJ$601,0))&" "&INDEX(DESK!$G$2:$G$601,MATCH($C8&"|3",DESK!$AJ$2:$AJ$601,0)),"")) | E8: =IF(O8="","",ROUND(INDEX(DESK!$W$2:$W$601,O8),1)) | F8: =IF(O8="","",INDEX(DESK!$Q$2:$Q$601,O8)+1) | G8: =IF(O8="","",IF((INDEX(DESK!$AU$2:$AU$601,O8)=1),IF((INDEX(DESK!$AC$2:$AC$601,O8)="YES"),"REPLIED YES on WhatsApp. Open Calendar 1, book the first free slot, WhatsApp them the time, log BOOKED.","REPLIED YES on WhatsApp. Send the WhatsApp (it has the booking link), log SENT_LINK."),IF(F8>=SETTINGS!$B$6,"LAST TRY. ","")&IF((INDEX(DESK!$S$2:$S$601,O8)="SENT_LINK"),"Open Calendar 1. Already booked? Log SELF_BOOKED. Not booked? Call, send the WhatsApp, log what happened.",IF((INDEX(DESK!$AC$2:$AC$601,O8)="YES"),"Call. They say yes? Open Calendar 1, book the first time that suits them, log BOOKED. No answer? Send the WhatsApp, log NO_ANSWER.","Call. They say yes? Send the WhatsApp (it has the booking link), log SENT_LINK. No answer? Send the WhatsApp, log NO_ANSWER.")))&IF(INDEX(DESK!$AS$2:$AS$601,O8)="FAILED"," (Our WhatsApp did not deliver: call only.)","")) | H8: =IF(O8="","",HYPERLINK("tel:+91"&C8,"Call "&C8)) | I8: =IF(O8="","",IF(LEN("https://wa.me/91"&C8&"?text="&_xlfn.ENCODEURL(M8))<=255,HYPERLINK("https://wa.me/91"&C8&"?text="&_xlfn.ENCODEURL(M8),"Open WhatsApp"),HYPERLINK("https://wa.me/91"&C8,"Open WhatsApp, paste column M"))) | J8: =IF(O8="","",HYPERLINK(INDEX(DESK!$AD$2:$AD$601,O8),INDEX(DESK!$B$2:$B$601,O8))) | K8: =IF(O8="","",IFERROR(HYPERLINK(INDEX(DESK!$AD$2:$AD$601,MATCH($C8&"|2",DESK!$AJ$2:$AJ$601,0)),INDEX(DESK!$B$2:$B$601,MATCH($C8&"|2",DESK!$AJ$2:$AJ$601,0))),"")) | L8: =IF(O8="","",IFERROR(HYPERLINK(INDEX(DESK!$AD$2:$AD$601,MATCH($C8&"|3",DESK!$AJ$2:$AJ$601,0)),INDEX(DESK!$B$2:$B$601,MATCH($C8&"|3",DESK!$AJ$2:$AJ$601,0))),"")) | M8: =IF(O8="","",SUBSTITUTE(SUBSTITUTE(SUBSTITUTE(SUBSTITUTE(INDEX(LISTS!$B$14:$B$19,MATCH(P8,LISTS!$A$14:$A$19,0))&IF(IF((INDEX(DESK!$AC$2:$AC$601,O8)="YES"),"",INDEX(DESK!$AD$2:$AD$601,O8))="",INDEX(LISTS!$B$14:$B$19,MATCH("YES",LISTS!$A$14:$A$19,0)),INDEX(LISTS!$B$14:$B$19,MATCH("NO",LISTS!$A$14:$A$19,0))),"{NAME}",INDEX(DESK!$AQ$2:$AQ$601,O8)),"{INTERN}",$B$2),"{COMPANY}",INDEX(DESK!$B$2:$B$601,O8)&IF(INDEX(DESK!$AA$2:$AA$601,O8)>1," and "&(INDEX(DESK!$AA$2:$AA$601,O8)-1)&" more","")),"{LINK}",IF((INDEX(DESK!$AC$2:$AC$601,O8)="YES"),"",INDEX(DESK!$AD$2:$AD$601,O8)))) | N8: =$B$2&"|"&A8 -> Ram|2 | O8: =IFERROR(MATCH(N8,DESK!$AI$2:$AI$601,0),"") | P8: =IF(O8="","",IF((INDEX(DESK!$S$2:$S$601,O8)="SENT_LINK"),"CHK",IF(F8=1,"T1",IF(F8>=SETTINGS!$B$6,"T3","T2"))))
A9: 3 | B9: =IF(O9="","",INDEX(DESK!$D$2:$D$601,O9)) | C9: =IF(O9="","",INDEX(DESK!$F$2:$F$601,O9)) | D9: =IF(O9="","",INDEX(DESK!$AW$2:$AW$601,O9)&" "&INDEX(DESK!$B$2:$B$601,O9)&" "&INDEX(DESK!$G$2:$G$601,O9)&IFERROR("; "&INDEX(DESK!$AW$2:$AW$601,MATCH($C9&"|2",DESK!$AJ$2:$AJ$601,0))&" "&INDEX(DESK!$B$2:$B$601,MATCH($C9&"|2",DESK!$AJ$2:$AJ$601,0))&" "&INDEX(DESK!$G$2:$G$601,MATCH($C9&"|2",DESK!$AJ$2:$AJ$601,0)),"")&IFERROR("; "&INDEX(DESK!$AW$2:$AW$601,MATCH($C9&"|3",DESK!$AJ$2:$AJ$601,0))&" "&INDEX(DESK!$B$2:$B$601,MATCH($C9&"|3",DESK!$AJ$2:$AJ$601,0))&" "&INDEX(DESK!$G$2:$G$601,MATCH($C9&"|3",DESK!$AJ$2:$AJ$601,0)),"")) | E9: =IF(O9="","",ROUND(INDEX(DESK!$W$2:$W$601,O9),1)) | F9: =IF(O9="","",INDEX(DESK!$Q$2:$Q$601,O9)+1) | G9: =IF(O9="","",IF((INDEX(DESK!$AU$2:$AU$601,O9)=1),IF((INDEX(DESK!$AC$2:$AC$601,O9)="YES"),"REPLIED YES on WhatsApp. Open Calendar 1, book the first free slot, WhatsApp them the time, log BOOKED.","REPLIED YES on WhatsApp. Send the WhatsApp (it has the booking link), log SENT_LINK."),IF(F9>=SETTINGS!$B$6,"LAST TRY. ","")&IF((INDEX(DESK!$S$2:$S$601,O9)="SENT_LINK"),"Open Calendar 1. Already booked? Log SELF_BOOKED. Not booked? Call, send the WhatsApp, log what happened.",IF((INDEX(DESK!$AC$2:$AC$601,O9)="YES"),"Call. They say yes? Open Calendar 1, book the first time that suits them, log BOOKED. No answer? Send the WhatsApp, log NO_ANSWER.","Call. They say yes? Send the WhatsApp (it has the booking link), log SENT_LINK. No answer? Send the WhatsApp, log NO_ANSWER.")))&IF(INDEX(DESK!$AS$2:$AS$601,O9)="FAILED"," (Our WhatsApp did not deliver: call only.)","")) | H9: =IF(O9="","",HYPERLINK("tel:+91"&C9,"Call "&C9)) | I9: =IF(O9="","",IF(LEN("https://wa.me/91"&C9&"?text="&_xlfn.ENCODEURL(M9))<=255,HYPERLINK("https://wa.me/91"&C9&"?text="&_xlfn.ENCODEURL(M9),"Open WhatsApp"),HYPERLINK("https://wa.me/91"&C9,"Open WhatsApp, paste column M"))) | J9: =IF(O9="","",HYPERLINK(INDEX(DESK!$AD$2:$AD$601,O9),INDEX(DESK!$B$2:$B$601,O9))) | K9: =IF(O9="","",IFERROR(HYPERLINK(INDEX(DESK!$AD$2:$AD$601,MATCH($C9&"|2",DESK!$AJ$2:$AJ$601,0)),INDEX(DESK!$B$2:$B$601,MATCH($C9&"|2",DESK!$AJ$2:$AJ$601,0))),"")) | L9: =IF(O9="","",IFERROR(HYPERLINK(INDEX(DESK!$AD$2:$AD$601,MATCH($C9&"|3",DESK!$AJ$2:$AJ$601,0)),INDEX(DESK!$B$2:$B$601,MATCH($C9&"|3",DESK!$AJ$2:$AJ$601,0))),"")) | M9: =IF(O9="","",SUBSTITUTE(SUBSTITUTE(SUBSTITUTE(SUBSTITUTE(INDEX(LISTS!$B$14:$B$19,MATCH(P9,LISTS!$A$14:$A$19,0))&IF(IF((INDEX(DESK!$AC$2:$AC$601,O9)="YES"),"",INDEX(DESK!$AD$2:$AD$601,O9))="",INDEX(LISTS!$B$14:$B$19,MATCH("YES",LISTS!$A$14:$A$19,0)),INDEX(LISTS!$B$14:$B$19,MATCH("NO",LISTS!$A$14:$A$19,0))),"{NAME}",INDEX(DESK!$AQ$2:$AQ$601,O9)),"{INTERN}",$B$2),"{COMPANY}",INDEX(DESK!$B$2:$B$601,O9)&IF(INDEX(DESK!$AA$2:$AA$601,O9)>1," and "&(INDEX(DESK!$AA$2:$AA$601,O9)-1)&" more","")),"{LINK}",IF((INDEX(DESK!$AC$2:$AC$601,O9)="YES"),"",INDEX(DESK!$AD$2:$AD$601,O9)))) | N9: =$B$2&"|"&A9 -> Ram|3 | O9: =IFERROR(MATCH(N9,DESK!$AI$2:$AI$601,0),"") | P9: =IF(O9="","",IF((INDEX(DESK!$S$2:$S$601,O9)="SENT_LINK"),"CHK",IF(F9=1,"T1",IF(F9>=SETTINGS!$B$6,"T3","T2"))))
A10: 4 | B10: =IF(O10="","",INDEX(DESK!$D$2:$D$601,O10)) | C10: =IF(O10="","",INDEX(DESK!$F$2:$F$601,O10)) | D10: =IF(O10="","",INDEX(DESK!$AW$2:$AW$601,O10)&" "&INDEX(DESK!$B$2:$B$601,O10)&" "&INDEX(DESK!$G$2:$G$601,O10)&IFERROR("; "&INDEX(DESK!$AW$2:$AW$601,MATCH($C10&"|2",DESK!$AJ$2:$AJ$601,0))&" "&INDEX(DESK!$B$2:$B$601,MATCH($C10&"|2",DESK!$AJ$2:$AJ$601,0))&" "&INDEX(DESK!$G$2:$G$601,MATCH($C10&"|2",DESK!$AJ$2:$AJ$601,0)),"")&IFERROR("; "&INDEX(DESK!$AW$2:$AW$601,MATCH($C10&"|3",DESK!$AJ$2:$AJ$601,0))&" "&INDEX(DESK!$B$2:$B$601,MATCH($C10&"|3",DESK!$AJ$2:$AJ$601,0))&" "&INDEX(DESK!$G$2:$G$601,MATCH($C10&"|3",DESK!$AJ$2:$AJ$601,0)),"")) | E10: =IF(O10="","",ROUND(INDEX(DESK!$W$2:$W$601,O10),1)) | F10: =IF(O10="","",INDEX(DESK!$Q$2:$Q$601,O10)+1) | G10: =IF(O10="","",IF((INDEX(DESK!$AU$2:$AU$601,O10)=1),IF((INDEX(DESK!$AC$2:$AC$601,O10)="YES"),"REPLIED YES on WhatsApp. Open Calendar 1, book the first free slot, WhatsApp them the time, log BOOKED.","REPLIED YES on WhatsApp. Send the WhatsApp (it has the booking link), log SENT_LINK."),IF(F10>=SETTINGS!$B$6,"LAST TRY. ","")&IF((INDEX(DESK!$S$2:$S$601,O10)="SENT_LINK"),"Open Calendar 1. Already booked? Log SELF_BOOKED. Not booked? Call, send the WhatsApp, log what happened.",IF((INDEX(DESK!$AC$2:$AC$601,O10)="YES"),"Call. They say yes? Open Calendar 1, book the first time that suits them, log BOOKED. No answer? Send the WhatsApp, log NO_ANSWER.","Call. They say yes? Send the WhatsApp (it has the booking link), log SENT_LINK. No answer? Send the WhatsApp, log NO_ANSWER.")))&IF(INDEX(DESK!$AS$2:$AS$601,O10)="FAILED"," (Our WhatsApp did not deliver: call only.)","")) | H10: =IF(O10="","",HYPERLINK("tel:+91"&C10,"Call "&C10)) | I10: =IF(O10="","",IF(LEN("https://wa.me/91"&C10&"?text="&_xlfn.ENCODEURL(M10))<=255,HYPERLINK("https://wa.me/91"&C10&"?text="&_xlfn.ENCODEURL(M10),"Open WhatsApp"),HYPERLINK("https://wa.me/91"&C10,"Open WhatsApp, paste column M"))) | J10: =IF(O10="","",HYPERLINK(INDEX(DESK!$AD$2:$AD$601,O10),INDEX(DESK!$B$2:$B$601,O10))) | K10: =IF(O10="","",IFERROR(HYPERLINK(INDEX(DESK!$AD$2:$AD$601,MATCH($C10&"|2",DESK!$AJ$2:$AJ$601,0)),INDEX(DESK!$B$2:$B$601,MATCH($C10&"|2",DESK!$AJ$2:$AJ$601,0))),"")) | L10: =IF(O10="","",IFERROR(HYPERLINK(INDEX(DESK!$AD$2:$AD$601,MATCH($C10&"|3",DESK!$AJ$2:$AJ$601,0)),INDEX(DESK!$B$2:$B$601,MATCH($C10&"|3",DESK!$AJ$2:$AJ$601,0))),"")) | M10: =IF(O10="","",SUBSTITUTE(SUBSTITUTE(SUBSTITUTE(SUBSTITUTE(INDEX(LISTS!$B$14:$B$19,MATCH(P10,LISTS!$A$14:$A$19,0))&IF(IF((INDEX(DESK!$AC$2:$AC$601,O10)="YES"),"",INDEX(DESK!$AD$2:$AD$601,O10))="",INDEX(LISTS!$B$14:$B$19,MATCH("YES",LISTS!$A$14:$A$19,0)),INDEX(LISTS!$B$14:$B$19,MATCH("NO",LISTS!$A$14:$A$19,0))),"{NAME}",INDEX(DESK!$AQ$2:$AQ$601,O10)),"{INTERN}",$B$2),"{COMPANY}",INDEX(DESK!$B$2:$B$601,O10)&IF(INDEX(DESK!$AA$2:$AA$601,O10)>1," and "&(INDEX(DESK!$AA$2:$AA$601,O10)-1)&" more","")),"{LINK}",IF((INDEX(DESK!$AC$2:$AC$601,O10)="YES"),"",INDEX(DESK!$AD$2:$AD$601,O10)))) | N10: =$B$2&"|"&A10 -> Ram|4 | O10: =IFERROR(MATCH(N10,DESK!$AI$2:$AI$601,0),"") | P10: =IF(O10="","",IF((INDEX(DESK!$S$2:$S$601,O10)="SENT_LINK"),"CHK",IF(F10=1,"T1",IF(F10>=SETTINGS!$B$6,"T3","T2"))))
A11: 5 | B11: =IF(O11="","",INDEX(DESK!$D$2:$D$601,O11)) | C11: =IF(O11="","",INDEX(DESK!$F$2:$F$601,O11)) | D11: =IF(O11="","",INDEX(DESK!$AW$2:$AW$601,O11)&" "&INDEX(DESK!$B$2:$B$601,O11)&" "&INDEX(DESK!$G$2:$G$601,O11)&IFERROR("; "&INDEX(DESK!$AW$2:$AW$601,MATCH($C11&"|2",DESK!$AJ$2:$AJ$601,0))&" "&INDEX(DESK!$B$2:$B$601,MATCH($C11&"|2",DESK!$AJ$2:$AJ$601,0))&" "&INDEX(DESK!$G$2:$G$601,MATCH($C11&"|2",DESK!$AJ$2:$AJ$601,0)),"")&IFERROR("; "&INDEX(DESK!$AW$2:$AW$601,MATCH($C11&"|3",DESK!$AJ$2:$AJ$601,0))&" "&INDEX(DESK!$B$2:$B$601,MATCH($C11&"|3",DESK!$AJ$2:$AJ$601,0))&" "&INDEX(DESK!$G$2:$G$601,MATCH($C11&"|3",DESK!$AJ$2:$AJ$601,0)),"")) | E11: =IF(O11="","",ROUND(INDEX(DESK!$W$2:$W$601,O11),1)) | F11: =IF(O11="","",INDEX(DESK!$Q$2:$Q$601,O11)+1) | G11: =IF(O11="","",IF((INDEX(DESK!$AU$2:$AU$601,O11)=1),IF((INDEX(DESK!$AC$2:$AC$601,O11)="YES"),"REPLIED YES on WhatsApp. Open Calendar 1, book the first free slot, WhatsApp them the time, log BOOKED.","REPLIED YES on WhatsApp. Send the WhatsApp (it has the booking link), log SENT_LINK."),IF(F11>=SETTINGS!$B$6,"LAST TRY. ","")&IF((INDEX(DESK!$S$2:$S$601,O11)="SENT_LINK"),"Open Calendar 1. Already booked? Log SELF_BOOKED. Not booked? Call, send the WhatsApp, log what happened.",IF((INDEX(DESK!$AC$2:$AC$601,O11)="YES"),"Call. They say yes? Open Calendar 1, book the first time that suits them, log BOOKED. No answer? Send the WhatsApp, log NO_ANSWER.","Call. They say yes? Send the WhatsApp (it has the booking link), log SENT_LINK. No answer? Send the WhatsApp, log NO_ANSWER.")))&IF(INDEX(DESK!$AS$2:$AS$601,O11)="FAILED"," (Our WhatsApp did not deliver: call only.)","")) | H11: =IF(O11="","",HYPERLINK("tel:+91"&C11,"Call "&C11)) | I11: =IF(O11="","",IF(LEN("https://wa.me/91"&C11&"?text="&_xlfn.ENCODEURL(M11))<=255,HYPERLINK("https://wa.me/91"&C11&"?text="&_xlfn.ENCODEURL(M11),"Open WhatsApp"),HYPERLINK("https://wa.me/91"&C11,"Open WhatsApp, paste column M"))) | J11: =IF(O11="","",HYPERLINK(INDEX(DESK!$AD$2:$AD$601,O11),INDEX(DESK!$B$2:$B$601,O11))) | K11: =IF(O11="","",IFERROR(HYPERLINK(INDEX(DESK!$AD$2:$AD$601,MATCH($C11&"|2",DESK!$AJ$2:$AJ$601,0)),INDEX(DESK!$B$2:$B$601,MATCH($C11&"|2",DESK!$AJ$2:$AJ$601,0))),"")) | L11: =IF(O11="","",IFERROR(HYPERLINK(INDEX(DESK!$AD$2:$AD$601,MATCH($C11&"|3",DESK!$AJ$2:$AJ$601,0)),INDEX(DESK!$B$2:$B$601,MATCH($C11&"|3",DESK!$AJ$2:$AJ$601,0))),"")) | M11: =IF(O11="","",SUBSTITUTE(SUBSTITUTE(SUBSTITUTE(SUBSTITUTE(INDEX(LISTS!$B$14:$B$19,MATCH(P11,LISTS!$A$14:$A$19,0))&IF(IF((INDEX(DESK!$AC$2:$AC$601,O11)="YES"),"",INDEX(DESK!$AD$2:$AD$601,O11))="",INDEX(LISTS!$B$14:$B$19,MATCH("YES",LISTS!$A$14:$A$19,0)),INDEX(LISTS!$B$14:$B$19,MATCH("NO",LISTS!$A$14:$A$19,0))),"{NAME}",INDEX(DESK!$AQ$2:$AQ$601,O11)),"{INTERN}",$B$2),"{COMPANY}",INDEX(DESK!$B$2:$B$601,O11)&IF(INDEX(DESK!$AA$2:$AA$601,O11)>1," and "&(INDEX(DESK!$AA$2:$AA$601,O11)-1)&" more","")),"{LINK}",IF((INDEX(DESK!$AC$2:$AC$601,O11)="YES"),"",INDEX(DESK!$AD$2:$AD$601,O11)))) | N11: =$B$2&"|"&A11 -> Ram|5 | O11: =IFERROR(MATCH(N11,DESK!$AI$2:$AI$601,0),"") | P11: =IF(O11="","",IF((INDEX(DESK!$S$2:$S$601,O11)="SENT_LINK"),"CHK",IF(F11=1,"T1",IF(F11>=SETTINGS!$B$6,"T3","T2"))))
A12: 6 | B12: =IF(O12="","",INDEX(DESK!$D$2:$D$601,O12)) | C12: =IF(O12="","",INDEX(DESK!$F$2:$F$601,O12)) | D12: =IF(O12="","",INDEX(DESK!$AW$2:$AW$601,O12)&" "&INDEX(DESK!$B$2:$B$601,O12)&" "&INDEX(DESK!$G$2:$G$601,O12)&IFERROR("; "&INDEX(DESK!$AW$2:$AW$601,MATCH($C12&"|2",DESK!$AJ$2:$AJ$601,0))&" "&INDEX(DESK!$B$2:$B$601,MATCH($C12&"|2",DESK!$AJ$2:$AJ$601,0))&" "&INDEX(DESK!$G$2:$G$601,MATCH($C12&"|2",DESK!$AJ$2:$AJ$601,0)),"")&IFERROR("; "&INDEX(DESK!$AW$2:$AW$601,MATCH($C12&"|3",DESK!$AJ$2:$AJ$601,0))&" "&INDEX(DESK!$B$2:$B$601,MATCH($C12&"|3",DESK!$AJ$2:$AJ$601,0))&" "&INDEX(DESK!$G$2:$G$601,MATCH($C12&"|3",DESK!$AJ$2:$AJ$601,0)),"")) | E12: =IF(O12="","",ROUND(INDEX(DESK!$W$2:$W$601,O12),1)) | F12: =IF(O12="","",INDEX(DESK!$Q$2:$Q$601,O12)+1) | G12: =IF(O12="","",IF((INDEX(DESK!$AU$2:$AU$601,O12)=1),IF((INDEX(DESK!$AC$2:$AC$601,O12)="YES"),"REPLIED YES on WhatsApp. Open Calendar 1, book the first free slot, WhatsApp them the time, log BOOKED.","REPLIED YES on WhatsApp. Send the WhatsApp (it has the booking link), log SENT_LINK."),IF(F12>=SETTINGS!$B$6,"LAST TRY. ","")&IF((INDEX(DESK!$S$2:$S$601,O12)="SENT_LINK"),"Open Calendar 1. Already booked? Log SELF_BOOKED. Not booked? Call, send the WhatsApp, log what happened.",IF((INDEX(DESK!$AC$2:$AC$601,O12)="YES"),"Call. They say yes? Open Calendar 1, book the first time that suits them, log BOOKED. No answer? Send the WhatsApp, log NO_ANSWER.","Call. They say yes? Send the WhatsApp (it has the booking link), log SENT_LINK. No answer? Send the WhatsApp, log NO_ANSWER.")))&IF(INDEX(DESK!$AS$2:$AS$601,O12)="FAILED"," (Our WhatsApp did not deliver: call only.)","")) | H12: =IF(O12="","",HYPERLINK("tel:+91"&C12,"Call "&C12)) | I12: =IF(O12="","",IF(LEN("https://wa.me/91"&C12&"?text="&_xlfn.ENCODEURL(M12))<=255,HYPERLINK("https://wa.me/91"&C12&"?text="&_xlfn.ENCODEURL(M12),"Open WhatsApp"),HYPERLINK("https://wa.me/91"&C12,"Open WhatsApp, paste column M"))) | J12: =IF(O12="","",HYPERLINK(INDEX(DESK!$AD$2:$AD$601,O12),INDEX(DESK!$B$2:$B$601,O12))) | K12: =IF(O12="","",IFERROR(HYPERLINK(INDEX(DESK!$AD$2:$AD$601,MATCH($C12&"|2",DESK!$AJ$2:$AJ$601,0)),INDEX(DESK!$B$2:$B$601,MATCH($C12&"|2",DESK!$AJ$2:$AJ$601,0))),"")) | L12: =IF(O12="","",IFERROR(HYPERLINK(INDEX(DESK!$AD$2:$AD$601,MATCH($C12&"|3",DESK!$AJ$2:$AJ$601,0)),INDEX(DESK!$B$2:$B$601,MATCH($C12&"|3",DESK!$AJ$2:$AJ$601,0))),"")) | M12: =IF(O12="","",SUBSTITUTE(SUBSTITUTE(SUBSTITUTE(SUBSTITUTE(INDEX(LISTS!$B$14:$B$19,MATCH(P12,LISTS!$A$14:$A$19,0))&IF(IF((INDEX(DESK!$AC$2:$AC$601,O12)="YES"),"",INDEX(DESK!$AD$2:$AD$601,O12))="",INDEX(LISTS!$B$14:$B$19,MATCH("YES",LISTS!$A$14:$A$19,0)),INDEX(LISTS!$B$14:$B$19,MATCH("NO",LISTS!$A$14:$A$19,0))),"{NAME}",INDEX(DESK!$AQ$2:$AQ$601,O12)),"{INTERN}",$B$2),"{COMPANY}",INDEX(DESK!$B$2:$B$601,O12)&IF(INDEX(DESK!$AA$2:$AA$601,O12)>1," and "&(INDEX(DESK!$AA$2:$AA$601,O12)-1)&" more","")),"{LINK}",IF((INDEX(DESK!$AC$2:$AC$601,O12)="YES"),"",INDEX(DESK!$AD$2:$AD$601,O12)))) | N12: =$B$2&"|"&A12 -> Ram|6 | O12: =IFERROR(MATCH(N12,DESK!$AI$2:$AI$601,0),"") | P12: =IF(O12="","",IF((INDEX(DESK!$S$2:$S$601,O12)="SENT_LINK"),"CHK",IF(F12=1,"T1",IF(F12>=SETTINGS!$B$6,"T3","T2"))))
A13: 7 | B13: =IF(O13="","",INDEX(DESK!$D$2:$D$601,O13)) | C13: =IF(O13="","",INDEX(DESK!$F$2:$F$601,O13)) | D13: =IF(O13="","",INDEX(DESK!$AW$2:$AW$601,O13)&" "&INDEX(DESK!$B$2:$B$601,O13)&" "&INDEX(DESK!$G$2:$G$601,O13)&IFERROR("; "&INDEX(DESK!$AW$2:$AW$601,MATCH($C13&"|2",DESK!$AJ$2:$AJ$601,0))&" "&INDEX(DESK!$B$2:$B$601,MATCH($C13&"|2",DESK!$AJ$2:$AJ$601,0))&" "&INDEX(DESK!$G$2:$G$601,MATCH($C13&"|2",DESK!$AJ$2:$AJ$601,0)),"")&IFERROR("; "&INDEX(DESK!$AW$2:$AW$601,MATCH($C13&"|3",DESK!$AJ$2:$AJ$601,0))&" "&INDEX(DESK!$B$2:$B$601,MATCH($C13&"|3",DESK!$AJ$2:$AJ$601,0))&" "&INDEX(DESK!$G$2:$G$601,MATCH($C13&"|3",DESK!$AJ$2:$AJ$601,0)),"")) | E13: =IF(O13="","",ROUND(INDEX(DESK!$W$2:$W$601,O13),1)) | F13: =IF(O13="","",INDEX(DESK!$Q$2:$Q$601,O13)+1) | G13: =IF(O13="","",IF((INDEX(DESK!$AU$2:$AU$601,O13)=1),IF((INDEX(DESK!$AC$2:$AC$601,O13)="YES"),"REPLIED YES on WhatsApp. Open Calendar 1, book the first free slot, WhatsApp them the time, log BOOKED.","REPLIED YES on WhatsApp. Send the WhatsApp (it has the booking link), log SENT_LINK."),IF(F13>=SETTINGS!$B$6,"LAST TRY. ","")&IF((INDEX(DESK!$S$2:$S$601,O13)="SENT_LINK"),"Open Calendar 1. Already booked? Log SELF_BOOKED. Not booked? Call, send the WhatsApp, log what happened.",IF((INDEX(DESK!$AC$2:$AC$601,O13)="YES"),"Call. They say yes? Open Calendar 1, book the first time that suits them, log BOOKED. No answer? Send the WhatsApp, log NO_ANSWER.","Call. They say yes? Send the WhatsApp (it has the booking link), log SENT_LINK. No answer? Send the WhatsApp, log NO_ANSWER.")))&IF(INDEX(DESK!$AS$2:$AS$601,O13)="FAILED"," (Our WhatsApp did not deliver: call only.)","")) | H13: =IF(O13="","",HYPERLINK("tel:+91"&C13,"Call "&C13)) | I13: =IF(O13="","",IF(LEN("https://wa.me/91"&C13&"?text="&_xlfn.ENCODEURL(M13))<=255,HYPERLINK("https://wa.me/91"&C13&"?text="&_xlfn.ENCODEURL(M13),"Open WhatsApp"),HYPERLINK("https://wa.me/91"&C13,"Open WhatsApp, paste column M"))) | J13: =IF(O13="","",HYPERLINK(INDEX(DESK!$AD$2:$AD$601,O13),INDEX(DESK!$B$2:$B$601,O13))) | K13: =IF(O13="","",IFERROR(HYPERLINK(INDEX(DESK!$AD$2:$AD$601,MATCH($C13&"|2",DESK!$AJ$2:$AJ$601,0)),INDEX(DESK!$B$2:$B$601,MATCH($C13&"|2",DESK!$AJ$2:$AJ$601,0))),"")) | L13: =IF(O13="","",IFERROR(HYPERLINK(INDEX(DESK!$AD$2:$AD$601,MATCH($C13&"|3",DESK!$AJ$2:$AJ$601,0)),INDEX(DESK!$B$2:$B$601,MATCH($C13&"|3",DESK!$AJ$2:$AJ$601,0))),"")) | M13: =IF(O13="","",SUBSTITUTE(SUBSTITUTE(SUBSTITUTE(SUBSTITUTE(INDEX(LISTS!$B$14:$B$19,MATCH(P13,LISTS!$A$14:$A$19,0))&IF(IF((INDEX(DESK!$AC$2:$AC$601,O13)="YES"),"",INDEX(DESK!$AD$2:$AD$601,O13))="",INDEX(LISTS!$B$14:$B$19,MATCH("YES",LISTS!$A$14:$A$19,0)),INDEX(LISTS!$B$14:$B$19,MATCH("NO",LISTS!$A$14:$A$19,0))),"{NAME}",INDEX(DESK!$AQ$2:$AQ$601,O13)),"{INTERN}",$B$2),"{COMPANY}",INDEX(DESK!$B$2:$B$601,O13)&IF(INDEX(DESK!$AA$2:$AA$601,O13)>1," and "&(INDEX(DESK!$AA$2:$AA$601,O13)-1)&" more","")),"{LINK}",IF((INDEX(DESK!$AC$2:$AC$601,O13)="YES"),"",INDEX(DESK!$AD$2:$AD$601,O13)))) | N13: =$B$2&"|"&A13 -> Ram|7 | O13: =IFERROR(MATCH(N13,DESK!$AI$2:$AI$601,0),"") | P13: =IF(O13="","",IF((INDEX(DESK!$S$2:$S$601,O13)="SENT_LINK"),"CHK",IF(F13=1,"T1",IF(F13>=SETTINGS!$B$6,"T3","T2"))))
A14: 8 | B14: =IF(O14="","",INDEX(DESK!$D$2:$D$601,O14)) | C14: =IF(O14="","",INDEX(DESK!$F$2:$F$601,O14)) | D14: =IF(O14="","",INDEX(DESK!$AW$2:$AW$601,O14)&" "&INDEX(DESK!$B$2:$B$601,O14)&" "&INDEX(DESK!$G$2:$G$601,O14)&IFERROR("; "&INDEX(DESK!$AW$2:$AW$601,MATCH($C14&"|2",DESK!$AJ$2:$AJ$601,0))&" "&INDEX(DESK!$B$2:$B$601,MATCH($C14&"|2",DESK!$AJ$2:$AJ$601,0))&" "&INDEX(DESK!$G$2:$G$601,MATCH($C14&"|2",DESK!$AJ$2:$AJ$601,0)),"")&IFERROR("; "&INDEX(DESK!$AW$2:$AW$601,MATCH($C14&"|3",DESK!$AJ$2:$AJ$601,0))&" "&INDEX(DESK!$B$2:$B$601,MATCH($C14&"|3",DESK!$AJ$2:$AJ$601,0))&" "&INDEX(DESK!$G$2:$G$601,MATCH($C14&"|3",DESK!$AJ$2:$AJ$601,0)),"")) | E14: =IF(O14="","",ROUND(INDEX(DESK!$W$2:$W$601,O14),1)) | F14: =IF(O14="","",INDEX(DESK!$Q$2:$Q$601,O14)+1) | G14: =IF(O14="","",IF((INDEX(DESK!$AU$2:$AU$601,O14)=1),IF((INDEX(DESK!$AC$2:$AC$601,O14)="YES"),"REPLIED YES on WhatsApp. Open Calendar 1, book the first free slot, WhatsApp them the time, log BOOKED.","REPLIED YES on WhatsApp. Send the WhatsApp (it has the booking link), log SENT_LINK."),IF(F14>=SETTINGS!$B$6,"LAST TRY. ","")&IF((INDEX(DESK!$S$2:$S$601,O14)="SENT_LINK"),"Open Calendar 1. Already booked? Log SELF_BOOKED. Not booked? Call, send the WhatsApp, log what happened.",IF((INDEX(DESK!$AC$2:$AC$601,O14)="YES"),"Call. They say yes? Open Calendar 1, book the first time that suits them, log BOOKED. No answer? Send the WhatsApp, log NO_ANSWER.","Call. They say yes? Send the WhatsApp (it has the booking link), log SENT_LINK. No answer? Send the WhatsApp, log NO_ANSWER.")))&IF(INDEX(DESK!$AS$2:$AS$601,O14)="FAILED"," (Our WhatsApp did not deliver: call only.)","")) | H14: =IF(O14="","",HYPERLINK("tel:+91"&C14,"Call "&C14)) | I14: =IF(O14="","",IF(LEN("https://wa.me/91"&C14&"?text="&_xlfn.ENCODEURL(M14))<=255,HYPERLINK("https://wa.me/91"&C14&"?text="&_xlfn.ENCODEURL(M14),"Open WhatsApp"),HYPERLINK("https://wa.me/91"&C14,"Open WhatsApp, paste column M"))) | J14: =IF(O14="","",HYPERLINK(INDEX(DESK!$AD$2:$AD$601,O14),INDEX(DESK!$B$2:$B$601,O14))) | K14: =IF(O14="","",IFERROR(HYPERLINK(INDEX(DESK!$AD$2:$AD$601,MATCH($C14&"|2",DESK!$AJ$2:$AJ$601,0)),INDEX(DESK!$B$2:$B$601,MATCH($C14&"|2",DESK!$AJ$2:$AJ$601,0))),"")) | L14: =IF(O14="","",IFERROR(HYPERLINK(INDEX(DESK!$AD$2:$AD$601,MATCH($C14&"|3",DESK!$AJ$2:$AJ$601,0)),INDEX(DESK!$B$2:$B$601,MATCH($C14&"|3",DESK!$AJ$2:$AJ$601,0))),"")) | M14: =IF(O14="","",SUBSTITUTE(SUBSTITUTE(SUBSTITUTE(SUBSTITUTE(INDEX(LISTS!$B$14:$B$19,MATCH(P14,LISTS!$A$14:$A$19,0))&IF(IF((INDEX(DESK!$AC$2:$AC$601,O14)="YES"),"",INDEX(DESK!$AD$2:$AD$601,O14))="",INDEX(LISTS!$B$14:$B$19,MATCH("YES",LISTS!$A$14:$A$19,0)),INDEX(LISTS!$B$14:$B$19,MATCH("NO",LISTS!$A$14:$A$19,0))),"{NAME}",INDEX(DESK!$AQ$2:$AQ$601,O14)),"{INTERN}",$B$2),"{COMPANY}",INDEX(DESK!$B$2:$B$601,O14)&IF(INDEX(DESK!$AA$2:$AA$601,O14)>1," and "&(INDEX(DESK!$AA$2:$AA$601,O14)-1)&" more","")),"{LINK}",IF((INDEX(DESK!$AC$2:$AC$601,O14)="YES"),"",INDEX(DESK!$AD$2:$AD$601,O14)))) | N14: =$B$2&"|"&A14 -> Ram|8 | O14: =IFERROR(MATCH(N14,DESK!$AI$2:$AI$601,0),"") | P14: =IF(O14="","",IF((INDEX(DESK!$S$2:$S$601,O14)="SENT_LINK"),"CHK",IF(F14=1,"T1",IF(F14>=SETTINGS!$B$6,"T3","T2"))))
A15: 9 | B15: =IF(O15="","",INDEX(DESK!$D$2:$D$601,O15)) | C15: =IF(O15="","",INDEX(DESK!$F$2:$F$601,O15)) | D15: =IF(O15="","",INDEX(DESK!$AW$2:$AW$601,O15)&" "&INDEX(DESK!$B$2:$B$601,O15)&" "&INDEX(DESK!$G$2:$G$601,O15)&IFERROR("; "&INDEX(DESK!$AW$2:$AW$601,MATCH($C15&"|2",DESK!$AJ$2:$AJ$601,0))&" "&INDEX(DESK!$B$2:$B$601,MATCH($C15&"|2",DESK!$AJ$2:$AJ$601,0))&" "&INDEX(DESK!$G$2:$G$601,MATCH($C15&"|2",DESK!$AJ$2:$AJ$601,0)),"")&IFERROR("; "&INDEX(DESK!$AW$2:$AW$601,MATCH($C15&"|3",DESK!$AJ$2:$AJ$601,0))&" "&INDEX(DESK!$B$2:$B$601,MATCH($C15&"|3",DESK!$AJ$2:$AJ$601,0))&" "&INDEX(DESK!$G$2:$G$601,MATCH($C15&"|3",DESK!$AJ$2:$AJ$601,0)),"")) | E15: =IF(O15="","",ROUND(INDEX(DESK!$W$2:$W$601,O15),1)) | F15: =IF(O15="","",INDEX(DESK!$Q$2:$Q$601,O15)+1) | G15: =IF(O15="","",IF((INDEX(DESK!$AU$2:$AU$601,O15)=1),IF((INDEX(DESK!$AC$2:$AC$601,O15)="YES"),"REPLIED YES on WhatsApp. Open Calendar 1, book the first free slot, WhatsApp them the time, log BOOKED.","REPLIED YES on WhatsApp. Send the WhatsApp (it has the booking link), log SENT_LINK."),IF(F15>=SETTINGS!$B$6,"LAST TRY. ","")&IF((INDEX(DESK!$S$2:$S$601,O15)="SENT_LINK"),"Open Calendar 1. Already booked? Log SELF_BOOKED. Not booked? Call, send the WhatsApp, log what happened.",IF((INDEX(DESK!$AC$2:$AC$601,O15)="YES"),"Call. They say yes? Open Calendar 1, book the first time that suits them, log BOOKED. No answer? Send the WhatsApp, log NO_ANSWER.","Call. They say yes? Send the WhatsApp (it has the booking link), log SENT_LINK. No answer? Send the WhatsApp, log NO_ANSWER.")))&IF(INDEX(DESK!$AS$2:$AS$601,O15)="FAILED"," (Our WhatsApp did not deliver: call only.)","")) | H15: =IF(O15="","",HYPERLINK("tel:+91"&C15,"Call "&C15)) | I15: =IF(O15="","",IF(LEN("https://wa.me/91"&C15&"?text="&_xlfn.ENCODEURL(M15))<=255,HYPERLINK("https://wa.me/91"&C15&"?text="&_xlfn.ENCODEURL(M15),"Open WhatsApp"),HYPERLINK("https://wa.me/91"&C15,"Open WhatsApp, paste column M"))) | J15: =IF(O15="","",HYPERLINK(INDEX(DESK!$AD$2:$AD$601,O15),INDEX(DESK!$B$2:$B$601,O15))) | K15: =IF(O15="","",IFERROR(HYPERLINK(INDEX(DESK!$AD$2:$AD$601,MATCH($C15&"|2",DESK!$AJ$2:$AJ$601,0)),INDEX(DESK!$B$2:$B$601,MATCH($C15&"|2",DESK!$AJ$2:$AJ$601,0))),"")) | L15: =IF(O15="","",IFERROR(HYPERLINK(INDEX(DESK!$AD$2:$AD$601,MATCH($C15&"|3",DESK!$AJ$2:$AJ$601,0)),INDEX(DESK!$B$2:$B$601,MATCH($C15&"|3",DESK!$AJ$2:$AJ$601,0))),"")) | M15: =IF(O15="","",SUBSTITUTE(SUBSTITUTE(SUBSTITUTE(SUBSTITUTE(INDEX(LISTS!$B$14:$B$19,MATCH(P15,LISTS!$A$14:$A$19,0))&IF(IF((INDEX(DESK!$AC$2:$AC$601,O15)="YES"),"",INDEX(DESK!$AD$2:$AD$601,O15))="",INDEX(LISTS!$B$14:$B$19,MATCH("YES",LISTS!$A$14:$A$19,0)),INDEX(LISTS!$B$14:$B$19,MATCH("NO",LISTS!$A$14:$A$19,0))),"{NAME}",INDEX(DESK!$AQ$2:$AQ$601,O15)),"{INTERN}",$B$2),"{COMPANY}",INDEX(DESK!$B$2:$B$601,O15)&IF(INDEX(DESK!$AA$2:$AA$601,O15)>1," and "&(INDEX(DESK!$AA$2:$AA$601,O15)-1)&" more","")),"{LINK}",IF((INDEX(DESK!$AC$2:$AC$601,O15)="YES"),"",INDEX(DESK!$AD$2:$AD$601,O15)))) | N15: =$B$2&"|"&A15 -> Ram|9 | O15: =IFERROR(MATCH(N15,DESK!$AI$2:$AI$601,0),"") | P15: =IF(O15="","",IF((INDEX(DESK!$S$2:$S$601,O15)="SENT_LINK"),"CHK",IF(F15=1,"T1",IF(F15>=SETTINGS!$B$6,"T3","T2"))))
A16: 10 | B16: =IF(O16="","",INDEX(DESK!$D$2:$D$601,O16)) | C16: =IF(O16="","",INDEX(DESK!$F$2:$F$601,O16)) | D16: =IF(O16="","",INDEX(DESK!$AW$2:$AW$601,O16)&" "&INDEX(DESK!$B$2:$B$601,O16)&" "&INDEX(DESK!$G$2:$G$601,O16)&IFERROR("; "&INDEX(DESK!$AW$2:$AW$601,MATCH($C16&"|2",DESK!$AJ$2:$AJ$601,0))&" "&INDEX(DESK!$B$2:$B$601,MATCH($C16&"|2",DESK!$AJ$2:$AJ$601,0))&" "&INDEX(DESK!$G$2:$G$601,MATCH($C16&"|2",DESK!$AJ$2:$AJ$601,0)),"")&IFERROR("; "&INDEX(DESK!$AW$2:$AW$601,MATCH($C16&"|3",DESK!$AJ$2:$AJ$601,0))&" "&INDEX(DESK!$B$2:$B$601,MATCH($C16&"|3",DESK!$AJ$2:$AJ$601,0))&" "&INDEX(DESK!$G$2:$G$601,MATCH($C16&"|3",DESK!$AJ$2:$AJ$601,0)),"")) | E16: =IF(O16="","",ROUND(INDEX(DESK!$W$2:$W$601,O16),1)) | F16: =IF(O16="","",INDEX(DESK!$Q$2:$Q$601,O16)+1) | G16: =IF(O16="","",IF((INDEX(DESK!$AU$2:$AU$601,O16)=1),IF((INDEX(DESK!$AC$2:$AC$601,O16)="YES"),"REPLIED YES on WhatsApp. Open Calendar 1, book the first free slot, WhatsApp them the time, log BOOKED.","REPLIED YES on WhatsApp. Send the WhatsApp (it has the booking link), log SENT_LINK."),IF(F16>=SETTINGS!$B$6,"LAST TRY. ","")&IF((INDEX(DESK!$S$2:$S$601,O16)="SENT_LINK"),"Open Calendar 1. Already booked? Log SELF_BOOKED. Not booked? Call, send the WhatsApp, log what happened.",IF((INDEX(DESK!$AC$2:$AC$601,O16)="YES"),"Call. They say yes? Open Calendar 1, book the first time that suits them, log BOOKED. No answer? Send the WhatsApp, log NO_ANSWER.","Call. They say yes? Send the WhatsApp (it has the booking link), log SENT_LINK. No answer? Send the WhatsApp, log NO_ANSWER.")))&IF(INDEX(DESK!$AS$2:$AS$601,O16)="FAILED"," (Our WhatsApp did not deliver: call only.)","")) | H16: =IF(O16="","",HYPERLINK("tel:+91"&C16,"Call "&C16)) | I16: =IF(O16="","",IF(LEN("https://wa.me/91"&C16&"?text="&_xlfn.ENCODEURL(M16))<=255,HYPERLINK("https://wa.me/91"&C16&"?text="&_xlfn.ENCODEURL(M16),"Open WhatsApp"),HYPERLINK("https://wa.me/91"&C16,"Open WhatsApp, paste column M"))) | J16: =IF(O16="","",HYPERLINK(INDEX(DESK!$AD$2:$AD$601,O16),INDEX(DESK!$B$2:$B$601,O16))) | K16: =IF(O16="","",IFERROR(HYPERLINK(INDEX(DESK!$AD$2:$AD$601,MATCH($C16&"|2",DESK!$AJ$2:$AJ$601,0)),INDEX(DESK!$B$2:$B$601,MATCH($C16&"|2",DESK!$AJ$2:$AJ$601,0))),"")) | L16: =IF(O16="","",IFERROR(HYPERLINK(INDEX(DESK!$AD$2:$AD$601,MATCH($C16&"|3",DESK!$AJ$2:$AJ$601,0)),INDEX(DESK!$B$2:$B$601,MATCH($C16&"|3",DESK!$AJ$2:$AJ$601,0))),"")) | M16: =IF(O16="","",SUBSTITUTE(SUBSTITUTE(SUBSTITUTE(SUBSTITUTE(INDEX(LISTS!$B$14:$B$19,MATCH(P16,LISTS!$A$14:$A$19,0))&IF(IF((INDEX(DESK!$AC$2:$AC$601,O16)="YES"),"",INDEX(DESK!$AD$2:$AD$601,O16))="",INDEX(LISTS!$B$14:$B$19,MATCH("YES",LISTS!$A$14:$A$19,0)),INDEX(LISTS!$B$14:$B$19,MATCH("NO",LISTS!$A$14:$A$19,0))),"{NAME}",INDEX(DESK!$AQ$2:$AQ$601,O16)),"{INTERN}",$B$2),"{COMPANY}",INDEX(DESK!$B$2:$B$601,O16)&IF(INDEX(DESK!$AA$2:$AA$601,O16)>1," and "&(INDEX(DESK!$AA$2:$AA$601,O16)-1)&" more","")),"{LINK}",IF((INDEX(DESK!$AC$2:$AC$601,O16)="YES"),"",INDEX(DESK!$AD$2:$AD$601,O16)))) | N16: =$B$2&"|"&A16 -> Ram|10 | O16: =IFERROR(MATCH(N16,DESK!$AI$2:$AI$601,0),"") | P16: =IF(O16="","",IF((INDEX(DESK!$S$2:$S$601,O16)="SENT_LINK"),"CHK",IF(F16=1,"T1",IF(F16>=SETTINGS!$B$6,"T3","T2"))))
A17: 11 | B17: =IF(O17="","",INDEX(DESK!$D$2:$D$601,O17)) | C17: =IF(O17="","",INDEX(DESK!$F$2:$F$601,O17)) | D17: =IF(O17="","",INDEX(DESK!$AW$2:$AW$601,O17)&" "&INDEX(DESK!$B$2:$B$601,O17)&" "&INDEX(DESK!$G$2:$G$601,O17)&IFERROR("; "&INDEX(DESK!$AW$2:$AW$601,MATCH($C17&"|2",DESK!$AJ$2:$AJ$601,0))&" "&INDEX(DESK!$B$2:$B$601,MATCH($C17&"|2",DESK!$AJ$2:$AJ$601,0))&" "&INDEX(DESK!$G$2:$G$601,MATCH($C17&"|2",DESK!$AJ$2:$AJ$601,0)),"")&IFERROR("; "&INDEX(DESK!$AW$2:$AW$601,MATCH($C17&"|3",DESK!$AJ$2:$AJ$601,0))&" "&INDEX(DESK!$B$2:$B$601,MATCH($C17&"|3",DESK!$AJ$2:$AJ$601,0))&" "&INDEX(DESK!$G$2:$G$601,MATCH($C17&"|3",DESK!$AJ$2:$AJ$601,0)),"")) | E17: =IF(O17="","",ROUND(INDEX(DESK!$W$2:$W$601,O17),1)) | F17: =IF(O17="","",INDEX(DESK!$Q$2:$Q$601,O17)+1) | G17: =IF(O17="","",IF((INDEX(DESK!$AU$2:$AU$601,O17)=1),IF((INDEX(DESK!$AC$2:$AC$601,O17)="YES"),"REPLIED YES on WhatsApp. Open Calendar 1, book the first free slot, WhatsApp them the time, log BOOKED.","REPLIED YES on WhatsApp. Send the WhatsApp (it has the booking link), log SENT_LINK."),IF(F17>=SETTINGS!$B$6,"LAST TRY. ","")&IF((INDEX(DESK!$S$2:$S$601,O17)="SENT_LINK"),"Open Calendar 1. Already booked? Log SELF_BOOKED. Not booked? Call, send the WhatsApp, log what happened.",IF((INDEX(DESK!$AC$2:$AC$601,O17)="YES"),"Call. They say yes? Open Calendar 1, book the first time that suits them, log BOOKED. No answer? Send the WhatsApp, log NO_ANSWER.","Call. They say yes? Send the WhatsApp (it has the booking link), log SENT_LINK. No answer? Send the WhatsApp, log NO_ANSWER.")))&IF(INDEX(DESK!$AS$2:$AS$601,O17)="FAILED"," (Our WhatsApp did not deliver: call only.)","")) | H17: =IF(O17="","",HYPERLINK("tel:+91"&C17,"Call "&C17)) | I17: =IF(O17="","",IF(LEN("https://wa.me/91"&C17&"?text="&_xlfn.ENCODEURL(M17))<=255,HYPERLINK("https://wa.me/91"&C17&"?text="&_xlfn.ENCODEURL(M17),"Open WhatsApp"),HYPERLINK("https://wa.me/91"&C17,"Open WhatsApp, paste column M"))) | J17: =IF(O17="","",HYPERLINK(INDEX(DESK!$AD$2:$AD$601,O17),INDEX(DESK!$B$2:$B$601,O17))) | K17: =IF(O17="","",IFERROR(HYPERLINK(INDEX(DESK!$AD$2:$AD$601,MATCH($C17&"|2",DESK!$AJ$2:$AJ$601,0)),INDEX(DESK!$B$2:$B$601,MATCH($C17&"|2",DESK!$AJ$2:$AJ$601,0))),"")) | L17: =IF(O17="","",IFERROR(HYPERLINK(INDEX(DESK!$AD$2:$AD$601,MATCH($C17&"|3",DESK!$AJ$2:$AJ$601,0)),INDEX(DESK!$B$2:$B$601,MATCH($C17&"|3",DESK!$AJ$2:$AJ$601,0))),"")) | M17: =IF(O17="","",SUBSTITUTE(SUBSTITUTE(SUBSTITUTE(SUBSTITUTE(INDEX(LISTS!$B$14:$B$19,MATCH(P17,LISTS!$A$14:$A$19,0))&IF(IF((INDEX(DESK!$AC$2:$AC$601,O17)="YES"),"",INDEX(DESK!$AD$2:$AD$601,O17))="",INDEX(LISTS!$B$14:$B$19,MATCH("YES",LISTS!$A$14:$A$19,0)),INDEX(LISTS!$B$14:$B$19,MATCH("NO",LISTS!$A$14:$A$19,0))),"{NAME}",INDEX(DESK!$AQ$2:$AQ$601,O17)),"{INTERN}",$B$2),"{COMPANY}",INDEX(DESK!$B$2:$B$601,O17)&IF(INDEX(DESK!$AA$2:$AA$601,O17)>1," and "&(INDEX(DESK!$AA$2:$AA$601,O17)-1)&" more","")),"{LINK}",IF((INDEX(DESK!$AC$2:$AC$601,O17)="YES"),"",INDEX(DESK!$AD$2:$AD$601,O17)))) | N17: =$B$2&"|"&A17 -> Ram|11 | O17: =IFERROR(MATCH(N17,DESK!$AI$2:$AI$601,0),"") | P17: =IF(O17="","",IF((INDEX(DESK!$S$2:$S$601,O17)="SENT_LINK"),"CHK",IF(F17=1,"T1",IF(F17>=SETTINGS!$B$6,"T3","T2"))))
A18: 12 | B18: =IF(O18="","",INDEX(DESK!$D$2:$D$601,O18)) | C18: =IF(O18="","",INDEX(DESK!$F$2:$F$601,O18)) | D18: =IF(O18="","",INDEX(DESK!$AW$2:$AW$601,O18)&" "&INDEX(DESK!$B$2:$B$601,O18)&" "&INDEX(DESK!$G$2:$G$601,O18)&IFERROR("; "&INDEX(DESK!$AW$2:$AW$601,MATCH($C18&"|2",DESK!$AJ$2:$AJ$601,0))&" "&INDEX(DESK!$B$2:$B$601,MATCH($C18&"|2",DESK!$AJ$2:$AJ$601,0))&" "&INDEX(DESK!$G$2:$G$601,MATCH($C18&"|2",DESK!$AJ$2:$AJ$601,0)),"")&IFERROR("; "&INDEX(DESK!$AW$2:$AW$601,MATCH($C18&"|3",DESK!$AJ$2:$AJ$601,0))&" "&INDEX(DESK!$B$2:$B$601,MATCH($C18&"|3",DESK!$AJ$2:$AJ$601,0))&" "&INDEX(DESK!$G$2:$G$601,MATCH($C18&"|3",DESK!$AJ$2:$AJ$601,0)),"")) | E18: =IF(O18="","",ROUND(INDEX(DESK!$W$2:$W$601,O18),1)) | F18: =IF(O18="","",INDEX(DESK!$Q$2:$Q$601,O18)+1) | G18: =IF(O18="","",IF((INDEX(DESK!$AU$2:$AU$601,O18)=1),IF((INDEX(DESK!$AC$2:$AC$601,O18)="YES"),"REPLIED YES on WhatsApp. Open Calendar 1, book the first free slot, WhatsApp them the time, log BOOKED.","REPLIED YES on WhatsApp. Send the WhatsApp (it has the booking link), log SENT_LINK."),IF(F18>=SETTINGS!$B$6,"LAST TRY. ","")&IF((INDEX(DESK!$S$2:$S$601,O18)="SENT_LINK"),"Open Calendar 1. Already booked? Log SELF_BOOKED. Not booked? Call, send the WhatsApp, log what happened.",IF((INDEX(DESK!$AC$2:$AC$601,O18)="YES"),"Call. They say yes? Open Calendar 1, book the first time that suits them, log BOOKED. No answer? Send the WhatsApp, log NO_ANSWER.","Call. They say yes? Send the WhatsApp (it has the booking link), log SENT_LINK. No answer? Send the WhatsApp, log NO_ANSWER.")))&IF(INDEX(DESK!$AS$2:$AS$601,O18)="FAILED"," (Our WhatsApp did not deliver: call only.)","")) | H18: =IF(O18="","",HYPERLINK("tel:+91"&C18,"Call "&C18)) | I18: =IF(O18="","",IF(LEN("https://wa.me/91"&C18&"?text="&_xlfn.ENCODEURL(M18))<=255,HYPERLINK("https://wa.me/91"&C18&"?text="&_xlfn.ENCODEURL(M18),"Open WhatsApp"),HYPERLINK("https://wa.me/91"&C18,"Open WhatsApp, paste column M"))) | J18: =IF(O18="","",HYPERLINK(INDEX(DESK!$AD$2:$AD$601,O18),INDEX(DESK!$B$2:$B$601,O18))) | K18: =IF(O18="","",IFERROR(HYPERLINK(INDEX(DESK!$AD$2:$AD$601,MATCH($C18&"|2",DESK!$AJ$2:$AJ$601,0)),INDEX(DESK!$B$2:$B$601,MATCH($C18&"|2",DESK!$AJ$2:$AJ$601,0))),"")) | L18: =IF(O18="","",IFERROR(HYPERLINK(INDEX(DESK!$AD$2:$AD$601,MATCH($C18&"|3",DESK!$AJ$2:$AJ$601,0)),INDEX(DESK!$B$2:$B$601,MATCH($C18&"|3",DESK!$AJ$2:$AJ$601,0))),"")) | M18: =IF(O18="","",SUBSTITUTE(SUBSTITUTE(SUBSTITUTE(SUBSTITUTE(INDEX(LISTS!$B$14:$B$19,MATCH(P18,LISTS!$A$14:$A$19,0))&IF(IF((INDEX(DESK!$AC$2:$AC$601,O18)="YES"),"",INDEX(DESK!$AD$2:$AD$601,O18))="",INDEX(LISTS!$B$14:$B$19,MATCH("YES",LISTS!$A$14:$A$19,0)),INDEX(LISTS!$B$14:$B$19,MATCH("NO",LISTS!$A$14:$A$19,0))),"{NAME}",INDEX(DESK!$AQ$2:$AQ$601,O18)),"{INTERN}",$B$2),"{COMPANY}",INDEX(DESK!$B$2:$B$601,O18)&IF(INDEX(DESK!$AA$2:$AA$601,O18)>1," and "&(INDEX(DESK!$AA$2:$AA$601,O18)-1)&" more","")),"{LINK}",IF((INDEX(DESK!$AC$2:$AC$601,O18)="YES"),"",INDEX(DESK!$AD$2:$AD$601,O18)))) | N18: =$B$2&"|"&A18 -> Ram|12 | O18: =IFERROR(MATCH(N18,DESK!$AI$2:$AI$601,0),"") | P18: =IF(O18="","",IF((INDEX(DESK!$S$2:$S$601,O18)="SENT_LINK"),"CHK",IF(F18=1,"T1",IF(F18>=SETTINGS!$B$6,"T3","T2"))))
... A31: 25 | B31: =IF(O31="","",INDEX(DESK!$D$2:$D$601,O31)) | C31: =IF(O31="","",INDEX(DESK!$F$2:$F$601,O31)) | D31: =IF(O31="","",INDEX(DESK!$AW$2:$AW$601,O31)&" "&INDEX(DESK!$B$2:$B$601,O31)&" "&INDEX(DESK!$G$2:$G$601,O31)&IFERROR("; "&INDEX(DESK!$AW$2:$AW$601,MATCH($C31&"|2",DESK!$AJ$2:$AJ$601,0))&" "&INDEX(DESK!$B$2:$B$601,MATCH($C31&"|2",DESK!$AJ$2:$AJ$601,0))&" "&INDEX(DESK!$G$2:$G$601,MATCH($C31&"|2",DESK!$AJ$2:$AJ$601,0)),"")&IFERROR("; "&INDEX(DESK!$AW$2:$AW$601,MATCH($C31&"|3",DESK!$AJ$2:$AJ$601,0))&" "&INDEX(DESK!$B$2:$B$601,MATCH($C31&"|3",DESK!$AJ$2:$AJ$601,0))&" "&INDEX(DESK!$G$2:$G$601,MATCH($C31&"|3",DESK!$AJ$2:$AJ$601,0)),"")) | E31: =IF(O31="","",ROUND(INDEX(DESK!$W$2:$W$601,O31),1)) | F31: =IF(O31="","",INDEX(DESK!$Q$2:$Q$601,O31)+1) | G31: =IF(O31="","",IF((INDEX(DESK!$AU$2:$AU$601,O31)=1),IF((INDEX(DESK!$AC$2:$AC$601,O31)="YES"),"REPLIED YES on WhatsApp. Open Calendar 1, book the first free slot, WhatsApp them the time, log BOOKED.","REPLIED YES on WhatsApp. Send the WhatsApp (it has the booking link), log SENT_LINK."),IF(F31>=SETTINGS!$B$6,"LAST TRY. ","")&IF((INDEX(DESK!$S$2:$S$601,O31)="SENT_LINK"),"Open Calendar 1. Already booked? Log SELF_BOOKED. Not booked? Call, send the WhatsApp, log what happened.",IF((INDEX(DESK!$AC$2:$AC$601,O31)="YES"),"Call. They say yes? Open Calendar 1, book the first time that suits them, log BOOKED. No answer? Send the WhatsApp, log NO_ANSWER.","Call. They say yes? Send the WhatsApp (it has the booking link), log SENT_LINK. No answer? Send the WhatsApp, log NO_ANSWER.")))&IF(INDEX(DESK!$AS$2:$AS$601,O31)="FAILED"," (Our WhatsApp did not deliver: call only.)","")) | H31: =IF(O31="","",HYPERLINK("tel:+91"&C31,"Call "&C31)) | I31: =IF(O31="","",IF(LEN("https://wa.me/91"&C31&"?text="&_xlfn.ENCODEURL(M31))<=255,HYPERLINK("https://wa.me/91"&C31&"?text="&_xlfn.ENCODEURL(M31),"Open WhatsApp"),HYPERLINK("https://wa.me/91"&C31,"Open WhatsApp, paste column M"))) | J31: =IF(O31="","",HYPERLINK(INDEX(DESK!$AD$2:$AD$601,O31),INDEX(DESK!$B$2:$B$601,O31))) | K31: =IF(O31="","",IFERROR(HYPERLINK(INDEX(DESK!$AD$2:$AD$601,MATCH($C31&"|2",DESK!$AJ$2:$AJ$601,0)),INDEX(DESK!$B$2:$B$601,MATCH($C31&"|2",DESK!$AJ$2:$AJ$601,0))),"")) | L31: =IF(O31="","",IFERROR(HYPERLINK(INDEX(DESK!$AD$2:$AD$601,MATCH($C31&"|3",DESK!$AJ$2:$AJ$601,0)),INDEX(DESK!$B$2:$B$601,MATCH($C31&"|3",DESK!$AJ$2:$AJ$601,0))),"")) | M31: =IF(O31="","",SUBSTITUTE(SUBSTITUTE(SUBSTITUTE(SUBSTITUTE(INDEX(LISTS!$B$14:$B$19,MATCH(P31,LISTS!$A$14:$A$19,0))&IF(IF((INDEX(DESK!$AC$2:$AC$601,O31)="YES"),"",INDEX(DESK!$AD$2:$AD$601,O31))="",INDEX(LISTS!$B$14:$B$19,MATCH("YES",LISTS!$A$14:$A$19,0)),INDEX(LISTS!$B$14:$B$19,MATCH("NO",LISTS!$A$14:$A$19,0))),"{NAME}",INDEX(DESK!$AQ$2:$AQ$601,O31)),"{INTERN}",$B$2),"{COMPANY}",INDEX(DESK!$B$2:$B$601,O31)&IF(INDEX(DESK!$AA$2:$AA$601,O31)>1," and "&(INDEX(DESK!$AA$2:$AA$601,O31)-1)&" more","")),"{LINK}",IF((INDEX(DESK!$AC$2:$AC$601,O31)="YES"),"",INDEX(DESK!$AD$2:$AD$601,O31)))) | N31: =$B$2&"|"&A31 -> Ram|25 | O31: =IFERROR(MATCH(N31,DESK!$AI$2:$AI$601,0),"") | P31: =IF(O31="","",IF((INDEX(DESK!$S$2:$S$601,O31)="SENT_LINK"),"CHK",IF(F31=1,"T1",IF(F31>=SETTINGS!$B$6,"T3","T2"))))

Sheet SHYAM
A1: SHYAM: your list. Start at the top. Do what column G says.
B2: Shyam | C2: Time now | D2: =SETTINGS!$B$4 -> 46309.828 | G2: =C3&" people waiting" -> 0 people waiting | N2: =SETTINGS!$B$14 -> 4
A3: =IF(ROUND(MOD(SETTINGS!$B$4,1)*1440,0)<ROUND(SETTINGS!$B$11*1440,0),"Your shift has not started. Nothing to do yet.",IF(ROUND(MOD(SETTINGS!$B$4,1)*1440,0)>=ROUND(SETTINGS!$B$12*1440,0),"Your shift is over. Thank you!",IF($C$3=0,"Nothing waiting right now. Check LOG column J for lines marked in orange.",""))) -> Nothing waiting right now. Check LOG column J for lines marked in orange. | C3: =SUMPRODUCT((DESK!$Z$2:$Z$601=$B$2)*(DESK!$AI$2:$AI$601<>"")) -> 0
A4: Reply or call-back? Phone: | E4: =IF($D$4="","",IF(IFERROR(MATCH($D$4&"|1",DESK!$AJ$2:$AJ$601,0),"")="","Not on the open list (already done, or wrong number).",INDEX(DESK!$AW$2:$AW$601,IFERROR(MATCH($D$4&"|1",DESK!$AJ$2:$AJ$601,0),""))&" "&INDEX(DESK!$B$2:$B$601,IFERROR(MATCH($D$4&"|1",DESK!$AJ$2:$AJ$601,0),""))&" "&INDEX(DESK!$G$2:$G$601,IFERROR(MATCH($D$4&"|1",DESK!$AJ$2:$AJ$601,0),""))&IF(IFERROR(MATCH($D$4&"|2",DESK!$AJ$2:$AJ$601,0),"")="","","; "&INDEX(DESK!$AW$2:$AW$601,IFERROR(MATCH($D$4&"|2",DESK!$AJ$2:$AJ$601,0),""))&" "&INDEX(DESK!$B$2:$B$601,IFERROR(MATCH($D$4&"|2",DESK!$AJ$2:$AJ$601,0),""))&" "&INDEX(DESK!$G$2:$G$601,IFERROR(MATCH($D$4&"|2",DESK!$AJ$2:$AJ$601,0),"")))&IF(IFERROR(MATCH($D$4&"|3",DESK!$AJ$2:$AJ$601,0),"")="","","; "&INDEX(DESK!$AW$2:$AW$601,IFERROR(MATCH($D$4&"|3",DESK!$AJ$2:$AJ$601,0),""))&" "&INDEX(DESK!$B$2:$B$601,IFERROR(MATCH($D$4&"|3",DESK!$AJ$2:$AJ$601,0),""))&" "&INDEX(DESK!$G$2:$G$601,IFERROR(MATCH($D$4&"|3",DESK!$AJ$2:$AJ$601,0),"")))&IF(INDEX(DESK!$AC$2:$AC$601,IFERROR(MATCH($D$4&"|1",DESK!$AJ$2:$AJ$601,0),""))="YES"," : they said yes? Book it, log BOOKED."," : send the link, log SENT_LINK."))) | J4: =IF(IFERROR(MATCH($D$4&"|1",DESK!$AJ$2:$AJ$601,0),"")="","",HYPERLINK(INDEX(DESK!$AD$2:$AD$601,IFERROR(MATCH($D$4&"|1",DESK!$AJ$2:$AJ$601,0),"")),"Calendar: "&INDEX(DESK!$B$2:$B$601,IFERROR(MATCH($D$4&"|1",DESK!$AJ$2:$AJ$601,0),"")))) | K4: =IF(IFERROR(MATCH($D$4&"|2",DESK!$AJ$2:$AJ$601,0),"")="","",HYPERLINK(INDEX(DESK!$AD$2:$AD$601,IFERROR(MATCH($D$4&"|2",DESK!$AJ$2:$AJ$601,0),"")),"Calendar: "&INDEX(DESK!$B$2:$B$601,IFERROR(MATCH($D$4&"|2",DESK!$AJ$2:$AJ$601,0),"")))) | L4: =IF(IFERROR(MATCH($D$4&"|3",DESK!$AJ$2:$AJ$601,0),"")="","",HYPERLINK(INDEX(DESK!$AD$2:$AD$601,IFERROR(MATCH($D$4&"|3",DESK!$AJ$2:$AJ$601,0),"")),"Calendar: "&INDEX(DESK!$B$2:$B$601,IFERROR(MATCH($D$4&"|3",DESK!$AJ$2:$AJ$601,0),""))))
A6: # | B6: Candidate | C6: Phone | D6: Interviews to book (request ID first) | E6: Hours left | F6: Try | G6: WHAT TO DO | H6: Call | I6: WhatsApp | J6: Calendar 1 | K6: Calendar 2 | L6: Calendar 3 | M6: Message (copy if WhatsApp opens empty) | N6: key | O6: row | P6: msg
A7: 1 | B7: =IF(O7="","",INDEX(DESK!$D$2:$D$601,O7)) | C7: =IF(O7="","",INDEX(DESK!$F$2:$F$601,O7)) | D7: =IF(O7="","",INDEX(DESK!$AW$2:$AW$601,O7)&" "&INDEX(DESK!$B$2:$B$601,O7)&" "&INDEX(DESK!$G$2:$G$601,O7)&IFERROR("; "&INDEX(DESK!$AW$2:$AW$601,MATCH($C7&"|2",DESK!$AJ$2:$AJ$601,0))&" "&INDEX(DESK!$B$2:$B$601,MATCH($C7&"|2",DESK!$AJ$2:$AJ$601,0))&" "&INDEX(DESK!$G$2:$G$601,MATCH($C7&"|2",DESK!$AJ$2:$AJ$601,0)),"")&IFERROR("; "&INDEX(DESK!$AW$2:$AW$601,MATCH($C7&"|3",DESK!$AJ$2:$AJ$601,0))&" "&INDEX(DESK!$B$2:$B$601,MATCH($C7&"|3",DESK!$AJ$2:$AJ$601,0))&" "&INDEX(DESK!$G$2:$G$601,MATCH($C7&"|3",DESK!$AJ$2:$AJ$601,0)),"")) | E7: =IF(O7="","",ROUND(INDEX(DESK!$W$2:$W$601,O7),1)) | F7: =IF(O7="","",INDEX(DESK!$Q$2:$Q$601,O7)+1) | G7: =IF(O7="","",IF((INDEX(DESK!$AU$2:$AU$601,O7)=1),IF((INDEX(DESK!$AC$2:$AC$601,O7)="YES"),"REPLIED YES on WhatsApp. Open Calendar 1, book the first free slot, WhatsApp them the time, log BOOKED.","REPLIED YES on WhatsApp. Send the WhatsApp (it has the booking link), log SENT_LINK."),IF(F7>=SETTINGS!$B$6,"LAST TRY. ","")&IF((INDEX(DESK!$S$2:$S$601,O7)="SENT_LINK"),"Open Calendar 1. Already booked? Log SELF_BOOKED. Not booked? Call, send the WhatsApp, log what happened.",IF((INDEX(DESK!$AC$2:$AC$601,O7)="YES"),"Call. They say yes? Open Calendar 1, book the first time that suits them, log BOOKED. No answer? Send the WhatsApp, log NO_ANSWER.","Call. They say yes? Send the WhatsApp (it has the booking link), log SENT_LINK. No answer? Send the WhatsApp, log NO_ANSWER.")))&IF(INDEX(DESK!$AS$2:$AS$601,O7)="FAILED"," (Our WhatsApp did not deliver: call only.)","")) | H7: =IF(O7="","",HYPERLINK("tel:+91"&C7,"Call "&C7)) | I7: =IF(O7="","",IF(LEN("https://wa.me/91"&C7&"?text="&_xlfn.ENCODEURL(M7))<=255,HYPERLINK("https://wa.me/91"&C7&"?text="&_xlfn.ENCODEURL(M7),"Open WhatsApp"),HYPERLINK("https://wa.me/91"&C7,"Open WhatsApp, paste column M"))) | J7: =IF(O7="","",HYPERLINK(INDEX(DESK!$AD$2:$AD$601,O7),INDEX(DESK!$B$2:$B$601,O7))) | K7: =IF(O7="","",IFERROR(HYPERLINK(INDEX(DESK!$AD$2:$AD$601,MATCH($C7&"|2",DESK!$AJ$2:$AJ$601,0)),INDEX(DESK!$B$2:$B$601,MATCH($C7&"|2",DESK!$AJ$2:$AJ$601,0))),"")) | L7: =IF(O7="","",IFERROR(HYPERLINK(INDEX(DESK!$AD$2:$AD$601,MATCH($C7&"|3",DESK!$AJ$2:$AJ$601,0)),INDEX(DESK!$B$2:$B$601,MATCH($C7&"|3",DESK!$AJ$2:$AJ$601,0))),"")) | M7: =IF(O7="","",SUBSTITUTE(SUBSTITUTE(SUBSTITUTE(SUBSTITUTE(INDEX(LISTS!$B$14:$B$19,MATCH(P7,LISTS!$A$14:$A$19,0))&IF(IF((INDEX(DESK!$AC$2:$AC$601,O7)="YES"),"",INDEX(DESK!$AD$2:$AD$601,O7))="",INDEX(LISTS!$B$14:$B$19,MATCH("YES",LISTS!$A$14:$A$19,0)),INDEX(LISTS!$B$14:$B$19,MATCH("NO",LISTS!$A$14:$A$19,0))),"{NAME}",INDEX(DESK!$AQ$2:$AQ$601,O7)),"{INTERN}",$B$2),"{COMPANY}",INDEX(DESK!$B$2:$B$601,O7)&IF(INDEX(DESK!$AA$2:$AA$601,O7)>1," and "&(INDEX(DESK!$AA$2:$AA$601,O7)-1)&" more","")),"{LINK}",IF((INDEX(DESK!$AC$2:$AC$601,O7)="YES"),"",INDEX(DESK!$AD$2:$AD$601,O7)))) | N7: =$B$2&"|"&A7 -> Shyam|1 | O7: =IFERROR(MATCH(N7,DESK!$AI$2:$AI$601,0),"") | P7: =IF(O7="","",IF((INDEX(DESK!$S$2:$S$601,O7)="SENT_LINK"),"CHK",IF(F7=1,"T1",IF(F7>=SETTINGS!$B$6,"T3","T2"))))
A8: 2 | B8: =IF(O8="","",INDEX(DESK!$D$2:$D$601,O8)) | C8: =IF(O8="","",INDEX(DESK!$F$2:$F$601,O8)) | D8: =IF(O8="","",INDEX(DESK!$AW$2:$AW$601,O8)&" "&INDEX(DESK!$B$2:$B$601,O8)&" "&INDEX(DESK!$G$2:$G$601,O8)&IFERROR("; "&INDEX(DESK!$AW$2:$AW$601,MATCH($C8&"|2",DESK!$AJ$2:$AJ$601,0))&" "&INDEX(DESK!$B$2:$B$601,MATCH($C8&"|2",DESK!$AJ$2:$AJ$601,0))&" "&INDEX(DESK!$G$2:$G$601,MATCH($C8&"|2",DESK!$AJ$2:$AJ$601,0)),"")&IFERROR("; "&INDEX(DESK!$AW$2:$AW$601,MATCH($C8&"|3",DESK!$AJ$2:$AJ$601,0))&" "&INDEX(DESK!$B$2:$B$601,MATCH($C8&"|3",DESK!$AJ$2:$AJ$601,0))&" "&INDEX(DESK!$G$2:$G$601,MATCH($C8&"|3",DESK!$AJ$2:$AJ$601,0)),"")) | E8: =IF(O8="","",ROUND(INDEX(DESK!$W$2:$W$601,O8),1)) | F8: =IF(O8="","",INDEX(DESK!$Q$2:$Q$601,O8)+1) | G8: =IF(O8="","",IF((INDEX(DESK!$AU$2:$AU$601,O8)=1),IF((INDEX(DESK!$AC$2:$AC$601,O8)="YES"),"REPLIED YES on WhatsApp. Open Calendar 1, book the first free slot, WhatsApp them the time, log BOOKED.","REPLIED YES on WhatsApp. Send the WhatsApp (it has the booking link), log SENT_LINK."),IF(F8>=SETTINGS!$B$6,"LAST TRY. ","")&IF((INDEX(DESK!$S$2:$S$601,O8)="SENT_LINK"),"Open Calendar 1. Already booked? Log SELF_BOOKED. Not booked? Call, send the WhatsApp, log what happened.",IF((INDEX(DESK!$AC$2:$AC$601,O8)="YES"),"Call. They say yes? Open Calendar 1, book the first time that suits them, log BOOKED. No answer? Send the WhatsApp, log NO_ANSWER.","Call. They say yes? Send the WhatsApp (it has the booking link), log SENT_LINK. No answer? Send the WhatsApp, log NO_ANSWER.")))&IF(INDEX(DESK!$AS$2:$AS$601,O8)="FAILED"," (Our WhatsApp did not deliver: call only.)","")) | H8: =IF(O8="","",HYPERLINK("tel:+91"&C8,"Call "&C8)) | I8: =IF(O8="","",IF(LEN("https://wa.me/91"&C8&"?text="&_xlfn.ENCODEURL(M8))<=255,HYPERLINK("https://wa.me/91"&C8&"?text="&_xlfn.ENCODEURL(M8),"Open WhatsApp"),HYPERLINK("https://wa.me/91"&C8,"Open WhatsApp, paste column M"))) | J8: =IF(O8="","",HYPERLINK(INDEX(DESK!$AD$2:$AD$601,O8),INDEX(DESK!$B$2:$B$601,O8))) | K8: =IF(O8="","",IFERROR(HYPERLINK(INDEX(DESK!$AD$2:$AD$601,MATCH($C8&"|2",DESK!$AJ$2:$AJ$601,0)),INDEX(DESK!$B$2:$B$601,MATCH($C8&"|2",DESK!$AJ$2:$AJ$601,0))),"")) | L8: =IF(O8="","",IFERROR(HYPERLINK(INDEX(DESK!$AD$2:$AD$601,MATCH($C8&"|3",DESK!$AJ$2:$AJ$601,0)),INDEX(DESK!$B$2:$B$601,MATCH($C8&"|3",DESK!$AJ$2:$AJ$601,0))),"")) | M8: =IF(O8="","",SUBSTITUTE(SUBSTITUTE(SUBSTITUTE(SUBSTITUTE(INDEX(LISTS!$B$14:$B$19,MATCH(P8,LISTS!$A$14:$A$19,0))&IF(IF((INDEX(DESK!$AC$2:$AC$601,O8)="YES"),"",INDEX(DESK!$AD$2:$AD$601,O8))="",INDEX(LISTS!$B$14:$B$19,MATCH("YES",LISTS!$A$14:$A$19,0)),INDEX(LISTS!$B$14:$B$19,MATCH("NO",LISTS!$A$14:$A$19,0))),"{NAME}",INDEX(DESK!$AQ$2:$AQ$601,O8)),"{INTERN}",$B$2),"{COMPANY}",INDEX(DESK!$B$2:$B$601,O8)&IF(INDEX(DESK!$AA$2:$AA$601,O8)>1," and "&(INDEX(DESK!$AA$2:$AA$601,O8)-1)&" more","")),"{LINK}",IF((INDEX(DESK!$AC$2:$AC$601,O8)="YES"),"",INDEX(DESK!$AD$2:$AD$601,O8)))) | N8: =$B$2&"|"&A8 -> Shyam|2 | O8: =IFERROR(MATCH(N8,DESK!$AI$2:$AI$601,0),"") | P8: =IF(O8="","",IF((INDEX(DESK!$S$2:$S$601,O8)="SENT_LINK"),"CHK",IF(F8=1,"T1",IF(F8>=SETTINGS!$B$6,"T3","T2"))))
A9: 3 | B9: =IF(O9="","",INDEX(DESK!$D$2:$D$601,O9)) | C9: =IF(O9="","",INDEX(DESK!$F$2:$F$601,O9)) | D9: =IF(O9="","",INDEX(DESK!$AW$2:$AW$601,O9)&" "&INDEX(DESK!$B$2:$B$601,O9)&" "&INDEX(DESK!$G$2:$G$601,O9)&IFERROR("; "&INDEX(DESK!$AW$2:$AW$601,MATCH($C9&"|2",DESK!$AJ$2:$AJ$601,0))&" "&INDEX(DESK!$B$2:$B$601,MATCH($C9&"|2",DESK!$AJ$2:$AJ$601,0))&" "&INDEX(DESK!$G$2:$G$601,MATCH($C9&"|2",DESK!$AJ$2:$AJ$601,0)),"")&IFERROR("; "&INDEX(DESK!$AW$2:$AW$601,MATCH($C9&"|3",DESK!$AJ$2:$AJ$601,0))&" "&INDEX(DESK!$B$2:$B$601,MATCH($C9&"|3",DESK!$AJ$2:$AJ$601,0))&" "&INDEX(DESK!$G$2:$G$601,MATCH($C9&"|3",DESK!$AJ$2:$AJ$601,0)),"")) | E9: =IF(O9="","",ROUND(INDEX(DESK!$W$2:$W$601,O9),1)) | F9: =IF(O9="","",INDEX(DESK!$Q$2:$Q$601,O9)+1) | G9: =IF(O9="","",IF((INDEX(DESK!$AU$2:$AU$601,O9)=1),IF((INDEX(DESK!$AC$2:$AC$601,O9)="YES"),"REPLIED YES on WhatsApp. Open Calendar 1, book the first free slot, WhatsApp them the time, log BOOKED.","REPLIED YES on WhatsApp. Send the WhatsApp (it has the booking link), log SENT_LINK."),IF(F9>=SETTINGS!$B$6,"LAST TRY. ","")&IF((INDEX(DESK!$S$2:$S$601,O9)="SENT_LINK"),"Open Calendar 1. Already booked? Log SELF_BOOKED. Not booked? Call, send the WhatsApp, log what happened.",IF((INDEX(DESK!$AC$2:$AC$601,O9)="YES"),"Call. They say yes? Open Calendar 1, book the first time that suits them, log BOOKED. No answer? Send the WhatsApp, log NO_ANSWER.","Call. They say yes? Send the WhatsApp (it has the booking link), log SENT_LINK. No answer? Send the WhatsApp, log NO_ANSWER.")))&IF(INDEX(DESK!$AS$2:$AS$601,O9)="FAILED"," (Our WhatsApp did not deliver: call only.)","")) | H9: =IF(O9="","",HYPERLINK("tel:+91"&C9,"Call "&C9)) | I9: =IF(O9="","",IF(LEN("https://wa.me/91"&C9&"?text="&_xlfn.ENCODEURL(M9))<=255,HYPERLINK("https://wa.me/91"&C9&"?text="&_xlfn.ENCODEURL(M9),"Open WhatsApp"),HYPERLINK("https://wa.me/91"&C9,"Open WhatsApp, paste column M"))) | J9: =IF(O9="","",HYPERLINK(INDEX(DESK!$AD$2:$AD$601,O9),INDEX(DESK!$B$2:$B$601,O9))) | K9: =IF(O9="","",IFERROR(HYPERLINK(INDEX(DESK!$AD$2:$AD$601,MATCH($C9&"|2",DESK!$AJ$2:$AJ$601,0)),INDEX(DESK!$B$2:$B$601,MATCH($C9&"|2",DESK!$AJ$2:$AJ$601,0))),"")) | L9: =IF(O9="","",IFERROR(HYPERLINK(INDEX(DESK!$AD$2:$AD$601,MATCH($C9&"|3",DESK!$AJ$2:$AJ$601,0)),INDEX(DESK!$B$2:$B$601,MATCH($C9&"|3",DESK!$AJ$2:$AJ$601,0))),"")) | M9: =IF(O9="","",SUBSTITUTE(SUBSTITUTE(SUBSTITUTE(SUBSTITUTE(INDEX(LISTS!$B$14:$B$19,MATCH(P9,LISTS!$A$14:$A$19,0))&IF(IF((INDEX(DESK!$AC$2:$AC$601,O9)="YES"),"",INDEX(DESK!$AD$2:$AD$601,O9))="",INDEX(LISTS!$B$14:$B$19,MATCH("YES",LISTS!$A$14:$A$19,0)),INDEX(LISTS!$B$14:$B$19,MATCH("NO",LISTS!$A$14:$A$19,0))),"{NAME}",INDEX(DESK!$AQ$2:$AQ$601,O9)),"{INTERN}",$B$2),"{COMPANY}",INDEX(DESK!$B$2:$B$601,O9)&IF(INDEX(DESK!$AA$2:$AA$601,O9)>1," and "&(INDEX(DESK!$AA$2:$AA$601,O9)-1)&" more","")),"{LINK}",IF((INDEX(DESK!$AC$2:$AC$601,O9)="YES"),"",INDEX(DESK!$AD$2:$AD$601,O9)))) | N9: =$B$2&"|"&A9 -> Shyam|3 | O9: =IFERROR(MATCH(N9,DESK!$AI$2:$AI$601,0),"") | P9: =IF(O9="","",IF((INDEX(DESK!$S$2:$S$601,O9)="SENT_LINK"),"CHK",IF(F9=1,"T1",IF(F9>=SETTINGS!$B$6,"T3","T2"))))
